2023-07-01T18:06:23.953234+0300 ERROR 'NoneType' object has no attribute 'current_task'
Traceback (most recent call last):

  File "<frozen runpy>", line 198, in _run_module_as_main
  File "<frozen runpy>", line 88, in _run_code

  File "C:\xStorage\Projects\PrometeyBot\root\tg\main.py", line 772, in <module>
    executor.start_polling(dispatcher=dp, skip_updates=True, on_startup=on_startup)
    │        │                        │                                 └ <function on_startup at 0x000002556C0776A0>
    │        │                        └ <aiogram.dispatcher.dispatcher.Dispatcher object at 0x000002556B9ADA10>
    │        └ <function start_polling at 0x000002554AC820C0>
    └ <module 'aiogram.utils.executor' from 'C:\\xStorage\\Projects\\PrometeyBot\\venv\\Lib\\site-packages\\aiogram\\utils\\executo...

  File "C:\xStorage\Projects\PrometeyBot\venv\Lib\site-packages\aiogram\utils\executor.py", line 45, in start_polling
    executor.start_polling(
    │        └ <function Executor.start_polling at 0x000002554AC82C00>
    └ <aiogram.utils.executor.Executor object at 0x000002556BF74C90>
  File "C:\xStorage\Projects\PrometeyBot\venv\Lib\site-packages\aiogram\utils\executor.py", line 323, in start_polling
    loop.run_forever()
    │    └ <function ProactorEventLoop.run_forever at 0x0000025548BEDF80>
    └ <ProactorEventLoop running=True closed=False debug=False>
  File "C:\Users\Dima Tatarin\AppData\Local\Programs\Python\Python311\Lib\asyncio\windows_events.py", line 321, in run_forever
    super().run_forever()
  File "C:\Users\Dima Tatarin\AppData\Local\Programs\Python\Python311\Lib\asyncio\base_events.py", line 607, in run_forever
    self._run_once()
    │    └ <function BaseEventLoop._run_once at 0x0000025548B33E20>
    └ <ProactorEventLoop running=True closed=False debug=False>
  File "C:\Users\Dima Tatarin\AppData\Local\Programs\Python\Python311\Lib\asyncio\base_events.py", line 1922, in _run_once
    handle._run()
    │      └ <function Handle._run at 0x0000025548A6DD00>
    └ <Handle <TaskStepMethWrapper object at 0x000002556C09AB30>()>
  File "C:\Users\Dima Tatarin\AppData\Local\Programs\Python\Python311\Lib\asyncio\events.py", line 80, in _run
    self._context.run(self._callback, *self._args)
    │    │            │    │           │    └ <member '_args' of 'Handle' objects>
    │    │            │    │           └ <Handle <TaskStepMethWrapper object at 0x000002556C09AB30>()>
    │    │            │    └ <member '_callback' of 'Handle' objects>
    │    │            └ <Handle <TaskStepMethWrapper object at 0x000002556C09AB30>()>
    │    └ <member '_context' of 'Handle' objects>
    └ <Handle <TaskStepMethWrapper object at 0x000002556C09AB30>()>
  File "C:\xStorage\Projects\PrometeyBot\venv\Lib\site-packages\aiogram\dispatcher\handler.py", line 117, in notify
    response = await handler_obj.handler(*args, **partial_data)
                     │           │        │       └ {}
                     │           │        └ (<Update {"update_id": 56642193, "message": {"message_id": 1739, "from": {"id": 459471362, "is_bot": false, "first_name": "Di...
                     │           └ <bound method Dispatcher.process_update of <aiogram.dispatcher.dispatcher.Dispatcher object at 0x000002556B9ADA10>>
                     └ Handler.HandlerObj(handler=<bound method Dispatcher.process_update of <aiogram.dispatcher.dispatcher.Dispatcher object at 0x0...
  File "C:\xStorage\Projects\PrometeyBot\venv\Lib\site-packages\aiogram\dispatcher\dispatcher.py", line 256, in process_update
    return await self.message_handlers.notify(update.message)
                 │    │                │      │      └ <aiogram.types.fields.Field object at 0x000002554A96D2D0>
                 │    │                │      └ <Update {"update_id": 56642193, "message": {"message_id": 1739, "from": {"id": 459471362, "is_bot": false, "first_name": "Dim...
                 │    │                └ <function Handler.notify at 0x000002554AB96340>
                 │    └ <aiogram.dispatcher.handler.Handler object at 0x000002554C5C1690>
                 └ <aiogram.dispatcher.dispatcher.Dispatcher object at 0x000002556B9ADA10>
  File "C:\xStorage\Projects\PrometeyBot\venv\Lib\site-packages\aiogram\dispatcher\handler.py", line 117, in notify
    response = await handler_obj.handler(*args, **partial_data)
                     │           │        │       └ {'state': <aiogram.dispatcher.storage.FSMContext object at 0x000002556D526FD0>}
                     │           │        └ (<Message {"message_id": 1739, "from": {"id": 459471362, "is_bot": false, "first_name": "Dima Tatarin", "last_name": "ᴵᵀ ᵖʳᵒᵈ...
                     │           └ <function check_task at 0x000002556C0760C0>
                     └ Handler.HandlerObj(handler=<function check_task at 0x000002556C0760C0>, spec=FullArgSpec(args=['message', 'state'], varargs=N...

> File "C:\xStorage\Projects\PrometeyBot\root\tg\main.py", line 370, in check_task
    task_number = task_obj.current_task
                  └ None

AttributeError: 'NoneType' object has no attribute 'current_task'
2023-07-01T18:06:24.142109+0300 ERROR 'NoneType' object has no attribute 'current_task'
Traceback (most recent call last):

  File "<frozen runpy>", line 198, in _run_module_as_main
  File "<frozen runpy>", line 88, in _run_code

  File "C:\xStorage\Projects\PrometeyBot\root\tg\main.py", line 772, in <module>
    executor.start_polling(dispatcher=dp, skip_updates=True, on_startup=on_startup)
    │        │                        │                                 └ <function on_startup at 0x000002556C0776A0>
    │        │                        └ <aiogram.dispatcher.dispatcher.Dispatcher object at 0x000002556B9ADA10>
    │        └ <function start_polling at 0x000002554AC820C0>
    └ <module 'aiogram.utils.executor' from 'C:\\xStorage\\Projects\\PrometeyBot\\venv\\Lib\\site-packages\\aiogram\\utils\\executo...

  File "C:\xStorage\Projects\PrometeyBot\venv\Lib\site-packages\aiogram\utils\executor.py", line 45, in start_polling
    executor.start_polling(
    │        └ <function Executor.start_polling at 0x000002554AC82C00>
    └ <aiogram.utils.executor.Executor object at 0x000002556BF74C90>
  File "C:\xStorage\Projects\PrometeyBot\venv\Lib\site-packages\aiogram\utils\executor.py", line 323, in start_polling
    loop.run_forever()
    │    └ <function ProactorEventLoop.run_forever at 0x0000025548BEDF80>
    └ <ProactorEventLoop running=True closed=False debug=False>
  File "C:\Users\Dima Tatarin\AppData\Local\Programs\Python\Python311\Lib\asyncio\windows_events.py", line 321, in run_forever
    super().run_forever()
  File "C:\Users\Dima Tatarin\AppData\Local\Programs\Python\Python311\Lib\asyncio\base_events.py", line 607, in run_forever
    self._run_once()
    │    └ <function BaseEventLoop._run_once at 0x0000025548B33E20>
    └ <ProactorEventLoop running=True closed=False debug=False>
  File "C:\Users\Dima Tatarin\AppData\Local\Programs\Python\Python311\Lib\asyncio\base_events.py", line 1922, in _run_once
    handle._run()
    │      └ <function Handle._run at 0x0000025548A6DD00>
    └ <Handle Task.task_wakeup(<Future finished result=None>)>
  File "C:\Users\Dima Tatarin\AppData\Local\Programs\Python\Python311\Lib\asyncio\events.py", line 80, in _run
    self._context.run(self._callback, *self._args)
    │    │            │    │           │    └ <member '_args' of 'Handle' objects>
    │    │            │    │           └ <Handle Task.task_wakeup(<Future finished result=None>)>
    │    │            │    └ <member '_callback' of 'Handle' objects>
    │    │            └ <Handle Task.task_wakeup(<Future finished result=None>)>
    │    └ <member '_context' of 'Handle' objects>
    └ <Handle Task.task_wakeup(<Future finished result=None>)>
  File "C:\xStorage\Projects\PrometeyBot\venv\Lib\site-packages\aiogram\dispatcher\handler.py", line 117, in notify
    response = await handler_obj.handler(*args, **partial_data)
                     │           │        │       └ {}
                     │           │        └ (<Update {"update_id": 56642193, "message": {"message_id": 1739, "from": {"id": 459471362, "is_bot": false, "first_name": "Di...
                     │           └ <bound method Dispatcher.process_update of <aiogram.dispatcher.dispatcher.Dispatcher object at 0x000002556B9ADA10>>
                     └ Handler.HandlerObj(handler=<bound method Dispatcher.process_update of <aiogram.dispatcher.dispatcher.Dispatcher object at 0x0...
  File "C:\xStorage\Projects\PrometeyBot\venv\Lib\site-packages\aiogram\dispatcher\dispatcher.py", line 256, in process_update
    return await self.message_handlers.notify(update.message)
                 │    │                │      │      └ <aiogram.types.fields.Field object at 0x000002554A96D2D0>
                 │    │                │      └ <Update {"update_id": 56642193, "message": {"message_id": 1739, "from": {"id": 459471362, "is_bot": false, "first_name": "Dim...
                 │    │                └ <function Handler.notify at 0x000002554AB96340>
                 │    └ <aiogram.dispatcher.handler.Handler object at 0x000002554C5C1690>
                 └ <aiogram.dispatcher.dispatcher.Dispatcher object at 0x000002556B9ADA10>
  File "C:\xStorage\Projects\PrometeyBot\venv\Lib\site-packages\aiogram\dispatcher\handler.py", line 117, in notify
    response = await handler_obj.handler(*args, **partial_data)
                     │           │        │       └ {'state': <aiogram.dispatcher.storage.FSMContext object at 0x000002556D526FD0>}
                     │           │        └ (<Message {"message_id": 1739, "from": {"id": 459471362, "is_bot": false, "first_name": "Dima Tatarin", "last_name": "ᴵᵀ ᵖʳᵒᵈ...
                     │           └ <function check_task at 0x000002556C0760C0>
                     └ Handler.HandlerObj(handler=<function check_task at 0x000002556C0760C0>, spec=FullArgSpec(args=['message', 'state'], varargs=N...

> File "C:\xStorage\Projects\PrometeyBot\root\tg\main.py", line 422, in check_task
    task.current_task += 1
    └ None

AttributeError: 'NoneType' object has no attribute 'current_task'
2023-07-01T18:39:25.819470+0300 ERROR An error has been caught in function '<module>', process 'MainProcess' (11784), thread 'MainThread' (11792):
Traceback (most recent call last):

  File "C:\xStorage\Projects\PrometeyBot\venv\Lib\site-packages\aiohttp\connector.py", line 1152, in _create_direct_connection
    hosts = await asyncio.shield(host_resolved)
                  │       │      └ <Task finished name='Task-2' coro=<TCPConnector._resolve_host() done, defined at C:\xStorage\Projects\PrometeyBot\venv\Lib\si...
                  │       └ <function shield at 0x000001F111749440>
                  └ <module 'asyncio' from 'C:\\Users\\Dima Tatarin\\AppData\\Local\\Programs\\Python\\Python311\\Lib\\asyncio\\__init__.py'>
  File "C:\xStorage\Projects\PrometeyBot\venv\Lib\site-packages\aiohttp\connector.py", line 874, in _resolve_host
    addrs = await self._resolver.resolve(host, port, family=self._family)
                  │    │         │       │     │            │    └ 0
                  │    │         │       │     │            └ <aiohttp.connector.TCPConnector object at 0x000001F134BAC150>
                  │    │         │       │     └ 443
                  │    │         │       └ 'api.telegram.org'
                  │    │         └ <function ThreadedResolver.resolve at 0x000001F1130DED40>
                  │    └ <aiohttp.resolver.ThreadedResolver object at 0x000001F134B992D0>
                  └ <aiohttp.connector.TCPConnector object at 0x000001F134BAC150>
  File "C:\xStorage\Projects\PrometeyBot\venv\Lib\site-packages\aiohttp\resolver.py", line 33, in resolve
    infos = await self._loop.getaddrinfo(
                  │    │     └ <function BaseEventLoop.getaddrinfo at 0x000001F111762AC0>
                  │    └ <ProactorEventLoop running=False closed=False debug=False>
                  └ <aiohttp.resolver.ThreadedResolver object at 0x000001F134B992D0>
  File "C:\Users\Dima Tatarin\AppData\Local\Programs\Python\Python311\Lib\asyncio\base_events.py", line 867, in getaddrinfo
    return await self.run_in_executor(
                 │    └ <function BaseEventLoop.run_in_executor at 0x000001F1117628E0>
                 └ <ProactorEventLoop running=False closed=False debug=False>
  File "C:\Users\Dima Tatarin\AppData\Local\Programs\Python\Python311\Lib\concurrent\futures\thread.py", line 58, in run
    result = self.fn(*self.args, **self.kwargs)
             │        │            └ None
             │        └ None
             └ None
  File "C:\Users\Dima Tatarin\AppData\Local\Programs\Python\Python311\Lib\socket.py", line 962, in getaddrinfo
    for res in _socket.getaddrinfo(host, port, family, type, proto, flags):
               │       │           │     │     │       │     │      └ <AddressInfo.AI_ADDRCONFIG: 1024>
               │       │           │     │     │       │     └ 0
               │       │           │     │     │       └ <SocketKind.SOCK_STREAM: 1>
               │       │           │     │     └ 0
               │       │           │     └ 443
               │       │           └ 'api.telegram.org'
               │       └ <built-in function getaddrinfo>
               └ <module '_socket' from 'C:\\Users\\Dima Tatarin\\AppData\\Local\\Programs\\Python\\Python311\\DLLs\\_socket.pyd'>

socket.gaierror: [Errno 11004] getaddrinfo failed


The above exception was the direct cause of the following exception:


Traceback (most recent call last):

  File "C:\xStorage\Projects\PrometeyBot\venv\Lib\site-packages\aiogram\bot\api.py", line 139, in make_request
    async with session.post(url, data=req, **kwargs) as response:
               │       │    │         │      └ {'proxy': None, 'proxy_auth': None, 'timeout': <object object at 0x000001F10F5E5610>}
               │       │    │         └ <aiohttp.formdata.FormData object at 0x000001F134B9B890>
               │       │    └ 'https://api.telegram.org/bot5724555976:AAFxd0Ipy9YSR4ZgYBDa-iypq-m1QK2-vp4/getMe'
               │       └ <function ClientSession.post at 0x000001F113165EE0>
               └ <aiohttp.client.ClientSession object at 0x000001F134C18E10>
  File "C:\xStorage\Projects\PrometeyBot\venv\Lib\site-packages\aiohttp\client.py", line 1141, in __aenter__
    self._resp = await self._coro
    │    │             │    └ <member '_coro' of '_BaseRequestContextManager' objects>
    │    │             └ <aiohttp.client._RequestContextManager object at 0x000001F134C77070>
    │    └ <member '_resp' of '_BaseRequestContextManager' objects>
    └ <aiohttp.client._RequestContextManager object at 0x000001F134C77070>
  File "C:\xStorage\Projects\PrometeyBot\venv\Lib\site-packages\aiohttp\client.py", line 536, in _request
    conn = await self._connector.connect(
                 │    └ None
                 └ <aiohttp.client.ClientSession object at 0x000001F134C18E10>
  File "C:\xStorage\Projects\PrometeyBot\venv\Lib\site-packages\aiohttp\connector.py", line 540, in connect
    proto = await self._create_connection(req, traces, timeout)
                  │    │                  │    │       └ ClientTimeout(total=300, connect=None, sock_read=None, sock_connect=None)
                  │    │                  │    └ []
                  │    │                  └ <aiohttp.client_reqrep.ClientRequest object at 0x000001F134B99D90>
                  │    └ <function TCPConnector._create_connection at 0x000001F113101080>
                  └ <aiohttp.connector.TCPConnector object at 0x000001F134BAC150>
  File "C:\xStorage\Projects\PrometeyBot\venv\Lib\site-packages\aiohttp\connector.py", line 901, in _create_connection
    _, proto = await self._create_direct_connection(req, traces, timeout)
                     │    │                         │    │       └ ClientTimeout(total=300, connect=None, sock_read=None, sock_connect=None)
                     │    │                         │    └ []
                     │    │                         └ <aiohttp.client_reqrep.ClientRequest object at 0x000001F134B99D90>
                     │    └ <function TCPConnector._create_direct_connection at 0x000001F113101760>
                     └ <aiohttp.connector.TCPConnector object at 0x000001F134BAC150>
  File "C:\xStorage\Projects\PrometeyBot\venv\Lib\site-packages\aiohttp\connector.py", line 1166, in _create_direct_connection
    raise ClientConnectorError(req.connection_key, exc) from exc
          │                    │   └ <property object at 0x000001F1130C7B50>
          │                    └ <aiohttp.client_reqrep.ClientRequest object at 0x000001F134B99D90>
          └ <class 'aiohttp.client_exceptions.ClientConnectorError'>

aiohttp.client_exceptions.ClientConnectorError: Cannot connect to host api.telegram.org:443 ssl:default [getaddrinfo failed]


During handling of the above exception, another exception occurred:


Traceback (most recent call last):

  File "<frozen runpy>", line 198, in _run_module_as_main
  File "<frozen runpy>", line 88, in _run_code

> File "C:\xStorage\Projects\PrometeyBot\root\tg\main.py", line 772, in <module>
    executor.start_polling(dispatcher=dp, skip_updates=True, on_startup=on_startup)
    │        │                        │                                 └ <function on_startup at 0x000001F134C97600>
    │        │                        └ <aiogram.dispatcher.dispatcher.Dispatcher object at 0x000001F1342D9450>
    │        └ <function start_polling at 0x000001F1138B2020>
    └ <module 'aiogram.utils.executor' from 'C:\\xStorage\\Projects\\PrometeyBot\\venv\\Lib\\site-packages\\aiogram\\utils\\executo...

  File "C:\xStorage\Projects\PrometeyBot\venv\Lib\site-packages\aiogram\utils\executor.py", line 45, in start_polling
    executor.start_polling(
    │        └ <function Executor.start_polling at 0x000001F1138B2B60>
    └ <aiogram.utils.executor.Executor object at 0x000001F134BAC9D0>
  File "C:\xStorage\Projects\PrometeyBot\venv\Lib\site-packages\aiogram\utils\executor.py", line 320, in start_polling
    loop.run_until_complete(self._startup_polling())
    │    │                  │    └ <function Executor._startup_polling at 0x000001F1138B2E80>
    │    │                  └ <aiogram.utils.executor.Executor object at 0x000001F134BAC9D0>
    │    └ <function BaseEventLoop.run_until_complete at 0x000001F111762020>
    └ <ProactorEventLoop running=False closed=False debug=False>
  File "C:\Users\Dima Tatarin\AppData\Local\Programs\Python\Python311\Lib\asyncio\base_events.py", line 653, in run_until_complete
    return future.result()
           │      └ <method 'result' of '_asyncio.Task' objects>
           └ <Task finished name='Task-1' coro=<Executor._startup_polling() done, defined at C:\xStorage\Projects\PrometeyBot\venv\Lib\sit...
  File "C:\xStorage\Projects\PrometeyBot\venv\Lib\site-packages\aiogram\utils\executor.py", line 372, in _startup_polling
    await self._welcome()
          │    └ <function Executor._welcome at 0x000001F1138B2D40>
          └ <aiogram.utils.executor.Executor object at 0x000001F134BAC9D0>
  File "C:\xStorage\Projects\PrometeyBot\venv\Lib\site-packages\aiogram\utils\executor.py", line 361, in _welcome
    user = await self.dispatcher.bot.me
                 │    │          │   └ <property object at 0x000001F1135C9B20>
                 │    │          └ <aiogram.bot.bot.Bot object at 0x000001F10F654F10>
                 │    └ <aiogram.dispatcher.dispatcher.Dispatcher object at 0x000001F1342D9450>
                 └ <aiogram.utils.executor.Executor object at 0x000001F134BAC9D0>
  File "C:\xStorage\Projects\PrometeyBot\venv\Lib\site-packages\aiogram\bot\bot.py", line 30, in me
    setattr(self, '_me', await self.get_me())
            │                  │    └ <function Bot.get_me at 0x000001F1135A76A0>
            │                  └ <aiogram.bot.bot.Bot object at 0x000001F10F654F10>
            └ <aiogram.bot.bot.Bot object at 0x000001F10F654F10>
  File "C:\xStorage\Projects\PrometeyBot\venv\Lib\site-packages\aiogram\bot\bot.py", line 233, in get_me
    result = await self.request(api.Methods.GET_ME, payload)
                   │    │       │   │       │       └ {}
                   │    │       │   │       └ <aiogram.utils.helper.Item object at 0x000001F11359F210>
                   │    │       │   └ <class 'aiogram.bot.api.Methods'>
                   │    │       └ <module 'aiogram.bot.api' from 'C:\\xStorage\\Projects\\PrometeyBot\\venv\\Lib\\site-packages\\aiogram\\bot\\api.py'>
                   │    └ <function BaseBot.request at 0x000001F1135A5B20>
                   └ <aiogram.bot.bot.Bot object at 0x000001F10F654F10>
  File "C:\xStorage\Projects\PrometeyBot\venv\Lib\site-packages\aiogram\bot\base.py", line 236, in request
    return await api.make_request(await self.get_session(), self.server, self.__token, method, data, files,
                 │   │                  │    │              │    │       │             │       │     └ None
                 │   │                  │    │              │    │       │             │       └ {}
                 │   │                  │    │              │    │       │             └ 'getMe'
                 │   │                  │    │              │    │       └ <aiogram.bot.bot.Bot object at 0x000001F10F654F10>
                 │   │                  │    │              │    └ TelegramAPIServer(base='https://api.telegram.org/bot{token}/{method}', file='https://api.telegram.org/file/bot{token}/{path}')
                 │   │                  │    │              └ <aiogram.bot.bot.Bot object at 0x000001F10F654F10>
                 │   │                  │    └ <function BaseBot.get_session at 0x000001F1135A5300>
                 │   │                  └ <aiogram.bot.bot.Bot object at 0x000001F10F654F10>
                 │   └ <function make_request at 0x000001F1135A4220>
                 └ <module 'aiogram.bot.api' from 'C:\\xStorage\\Projects\\PrometeyBot\\venv\\Lib\\site-packages\\aiogram\\bot\\api.py'>
  File "C:\xStorage\Projects\PrometeyBot\venv\Lib\site-packages\aiogram\bot\api.py", line 142, in make_request
    raise exceptions.NetworkError(f"aiohttp client throws an error: {e.__class__.__name__}: {e}")
          │          └ <class 'aiogram.utils.exceptions.NetworkError'>
          └ <module 'aiogram.utils.exceptions' from 'C:\\xStorage\\Projects\\PrometeyBot\\venv\\Lib\\site-packages\\aiogram\\utils\\excep...

aiogram.utils.exceptions.NetworkError: Aiohttp client throws an error: ClientConnectorError: Cannot connect to host api.telegram.org:443 ssl:default [getaddrinfo failed]
2023-07-01T18:39:39.500160+0300 ERROR An error has been caught in function '<module>', process 'MainProcess' (11696), thread 'MainThread' (11704):
Traceback (most recent call last):

  File "C:\xStorage\Projects\PrometeyBot\venv\Lib\site-packages\aiohttp\connector.py", line 1152, in _create_direct_connection
    hosts = await asyncio.shield(host_resolved)
                  │       │      └ <Task finished name='Task-2' coro=<TCPConnector._resolve_host() done, defined at C:\xStorage\Projects\PrometeyBot\venv\Lib\si...
                  │       └ <function shield at 0x00000238330D9440>
                  └ <module 'asyncio' from 'C:\\Users\\Dima Tatarin\\AppData\\Local\\Programs\\Python\\Python311\\Lib\\asyncio\\__init__.py'>
  File "C:\xStorage\Projects\PrometeyBot\venv\Lib\site-packages\aiohttp\connector.py", line 874, in _resolve_host
    addrs = await self._resolver.resolve(host, port, family=self._family)
                  │    │         │       │     │            │    └ 0
                  │    │         │       │     │            └ <aiohttp.connector.TCPConnector object at 0x000002385610D390>
                  │    │         │       │     └ 443
                  │    │         │       └ 'api.telegram.org'
                  │    │         └ <function ThreadedResolver.resolve at 0x00000238349FED40>
                  │    └ <aiohttp.resolver.ThreadedResolver object at 0x00000238564B19D0>
                  └ <aiohttp.connector.TCPConnector object at 0x000002385610D390>
  File "C:\xStorage\Projects\PrometeyBot\venv\Lib\site-packages\aiohttp\resolver.py", line 33, in resolve
    infos = await self._loop.getaddrinfo(
                  │    │     └ <function BaseEventLoop.getaddrinfo at 0x00000238330E2AC0>
                  │    └ <ProactorEventLoop running=False closed=False debug=False>
                  └ <aiohttp.resolver.ThreadedResolver object at 0x00000238564B19D0>
  File "C:\Users\Dima Tatarin\AppData\Local\Programs\Python\Python311\Lib\asyncio\base_events.py", line 867, in getaddrinfo
    return await self.run_in_executor(
                 │    └ <function BaseEventLoop.run_in_executor at 0x00000238330E28E0>
                 └ <ProactorEventLoop running=False closed=False debug=False>
  File "C:\Users\Dima Tatarin\AppData\Local\Programs\Python\Python311\Lib\concurrent\futures\thread.py", line 58, in run
    result = self.fn(*self.args, **self.kwargs)
             │        │            └ None
             │        └ None
             └ None
  File "C:\Users\Dima Tatarin\AppData\Local\Programs\Python\Python311\Lib\socket.py", line 962, in getaddrinfo
    for res in _socket.getaddrinfo(host, port, family, type, proto, flags):
               │       │           │     │     │       │     │      └ <AddressInfo.AI_ADDRCONFIG: 1024>
               │       │           │     │     │       │     └ 0
               │       │           │     │     │       └ <SocketKind.SOCK_STREAM: 1>
               │       │           │     │     └ 0
               │       │           │     └ 443
               │       │           └ 'api.telegram.org'
               │       └ <built-in function getaddrinfo>
               └ <module '_socket' from 'C:\\Users\\Dima Tatarin\\AppData\\Local\\Programs\\Python\\Python311\\DLLs\\_socket.pyd'>

socket.gaierror: [Errno 11004] getaddrinfo failed


The above exception was the direct cause of the following exception:


Traceback (most recent call last):

  File "C:\xStorage\Projects\PrometeyBot\venv\Lib\site-packages\aiogram\bot\api.py", line 139, in make_request
    async with session.post(url, data=req, **kwargs) as response:
               │       │    │         │      └ {'proxy': None, 'proxy_auth': None, 'timeout': <object object at 0x0000023830EB5610>}
               │       │    │         └ <aiohttp.formdata.FormData object at 0x00000238564B9350>
               │       │    └ 'https://api.telegram.org/bot5724555976:AAFxd0Ipy9YSR4ZgYBDa-iypq-m1QK2-vp4/getMe'
               │       └ <function ClientSession.post at 0x0000023834A85EE0>
               └ <aiohttp.client.ClientSession object at 0x00000238564B8DD0>
  File "C:\xStorage\Projects\PrometeyBot\venv\Lib\site-packages\aiohttp\client.py", line 1141, in __aenter__
    self._resp = await self._coro
    │    │             │    └ <member '_coro' of '_BaseRequestContextManager' objects>
    │    │             └ <aiohttp.client._RequestContextManager object at 0x000002385757ABF0>
    │    └ <member '_resp' of '_BaseRequestContextManager' objects>
    └ <aiohttp.client._RequestContextManager object at 0x000002385757ABF0>
  File "C:\xStorage\Projects\PrometeyBot\venv\Lib\site-packages\aiohttp\client.py", line 536, in _request
    conn = await self._connector.connect(
                 │    └ None
                 └ <aiohttp.client.ClientSession object at 0x00000238564B8DD0>
  File "C:\xStorage\Projects\PrometeyBot\venv\Lib\site-packages\aiohttp\connector.py", line 540, in connect
    proto = await self._create_connection(req, traces, timeout)
                  │    │                  │    │       └ ClientTimeout(total=300, connect=None, sock_read=None, sock_connect=None)
                  │    │                  │    └ []
                  │    │                  └ <aiohttp.client_reqrep.ClientRequest object at 0x00000238564B1E50>
                  │    └ <function TCPConnector._create_connection at 0x0000023834A21080>
                  └ <aiohttp.connector.TCPConnector object at 0x000002385610D390>
  File "C:\xStorage\Projects\PrometeyBot\venv\Lib\site-packages\aiohttp\connector.py", line 901, in _create_connection
    _, proto = await self._create_direct_connection(req, traces, timeout)
                     │    │                         │    │       └ ClientTimeout(total=300, connect=None, sock_read=None, sock_connect=None)
                     │    │                         │    └ []
                     │    │                         └ <aiohttp.client_reqrep.ClientRequest object at 0x00000238564B1E50>
                     │    └ <function TCPConnector._create_direct_connection at 0x0000023834A21760>
                     └ <aiohttp.connector.TCPConnector object at 0x000002385610D390>
  File "C:\xStorage\Projects\PrometeyBot\venv\Lib\site-packages\aiohttp\connector.py", line 1166, in _create_direct_connection
    raise ClientConnectorError(req.connection_key, exc) from exc
          │                    │   └ <property object at 0x00000238349E7B50>
          │                    └ <aiohttp.client_reqrep.ClientRequest object at 0x00000238564B1E50>
          └ <class 'aiohttp.client_exceptions.ClientConnectorError'>

aiohttp.client_exceptions.ClientConnectorError: Cannot connect to host api.telegram.org:443 ssl:default [getaddrinfo failed]


During handling of the above exception, another exception occurred:


Traceback (most recent call last):

  File "<frozen runpy>", line 198, in _run_module_as_main
  File "<frozen runpy>", line 88, in _run_code

> File "C:\xStorage\Projects\PrometeyBot\root\tg\main.py", line 772, in <module>
    executor.start_polling(dispatcher=dp, skip_updates=True, on_startup=on_startup)
    │        │                        │                                 └ <function on_startup at 0x0000023857597600>
    │        │                        └ <aiogram.dispatcher.dispatcher.Dispatcher object at 0x0000023855FC1ED0>
    │        └ <function start_polling at 0x00000238351D2020>
    └ <module 'aiogram.utils.executor' from 'C:\\xStorage\\Projects\\PrometeyBot\\venv\\Lib\\site-packages\\aiogram\\utils\\executo...

  File "C:\xStorage\Projects\PrometeyBot\venv\Lib\site-packages\aiogram\utils\executor.py", line 45, in start_polling
    executor.start_polling(
    │        └ <function Executor.start_polling at 0x00000238351D2B60>
    └ <aiogram.utils.executor.Executor object at 0x000002385759DF10>
  File "C:\xStorage\Projects\PrometeyBot\venv\Lib\site-packages\aiogram\utils\executor.py", line 320, in start_polling
    loop.run_until_complete(self._startup_polling())
    │    │                  │    └ <function Executor._startup_polling at 0x00000238351D2E80>
    │    │                  └ <aiogram.utils.executor.Executor object at 0x000002385759DF10>
    │    └ <function BaseEventLoop.run_until_complete at 0x00000238330E2020>
    └ <ProactorEventLoop running=False closed=False debug=False>
  File "C:\Users\Dima Tatarin\AppData\Local\Programs\Python\Python311\Lib\asyncio\base_events.py", line 653, in run_until_complete
    return future.result()
           │      └ <method 'result' of '_asyncio.Task' objects>
           └ <Task finished name='Task-1' coro=<Executor._startup_polling() done, defined at C:\xStorage\Projects\PrometeyBot\venv\Lib\sit...
  File "C:\xStorage\Projects\PrometeyBot\venv\Lib\site-packages\aiogram\utils\executor.py", line 372, in _startup_polling
    await self._welcome()
          │    └ <function Executor._welcome at 0x00000238351D2D40>
          └ <aiogram.utils.executor.Executor object at 0x000002385759DF10>
  File "C:\xStorage\Projects\PrometeyBot\venv\Lib\site-packages\aiogram\utils\executor.py", line 361, in _welcome
    user = await self.dispatcher.bot.me
                 │    │          │   └ <property object at 0x0000023834EED940>
                 │    │          └ <aiogram.bot.bot.Bot object at 0x0000023830F24F10>
                 │    └ <aiogram.dispatcher.dispatcher.Dispatcher object at 0x0000023855FC1ED0>
                 └ <aiogram.utils.executor.Executor object at 0x000002385759DF10>
  File "C:\xStorage\Projects\PrometeyBot\venv\Lib\site-packages\aiogram\bot\bot.py", line 30, in me
    setattr(self, '_me', await self.get_me())
            │                  │    └ <function Bot.get_me at 0x0000023834EC76A0>
            │                  └ <aiogram.bot.bot.Bot object at 0x0000023830F24F10>
            └ <aiogram.bot.bot.Bot object at 0x0000023830F24F10>
  File "C:\xStorage\Projects\PrometeyBot\venv\Lib\site-packages\aiogram\bot\bot.py", line 233, in get_me
    result = await self.request(api.Methods.GET_ME, payload)
                   │    │       │   │       │       └ {}
                   │    │       │   │       └ <aiogram.utils.helper.Item object at 0x0000023834EBEFD0>
                   │    │       │   └ <class 'aiogram.bot.api.Methods'>
                   │    │       └ <module 'aiogram.bot.api' from 'C:\\xStorage\\Projects\\PrometeyBot\\venv\\Lib\\site-packages\\aiogram\\bot\\api.py'>
                   │    └ <function BaseBot.request at 0x0000023834EC5B20>
                   └ <aiogram.bot.bot.Bot object at 0x0000023830F24F10>
  File "C:\xStorage\Projects\PrometeyBot\venv\Lib\site-packages\aiogram\bot\base.py", line 236, in request
    return await api.make_request(await self.get_session(), self.server, self.__token, method, data, files,
                 │   │                  │    │              │    │       │             │       │     └ None
                 │   │                  │    │              │    │       │             │       └ {}
                 │   │                  │    │              │    │       │             └ 'getMe'
                 │   │                  │    │              │    │       └ <aiogram.bot.bot.Bot object at 0x0000023830F24F10>
                 │   │                  │    │              │    └ TelegramAPIServer(base='https://api.telegram.org/bot{token}/{method}', file='https://api.telegram.org/file/bot{token}/{path}')
                 │   │                  │    │              └ <aiogram.bot.bot.Bot object at 0x0000023830F24F10>
                 │   │                  │    └ <function BaseBot.get_session at 0x0000023834EC5300>
                 │   │                  └ <aiogram.bot.bot.Bot object at 0x0000023830F24F10>
                 │   └ <function make_request at 0x0000023834EC4220>
                 └ <module 'aiogram.bot.api' from 'C:\\xStorage\\Projects\\PrometeyBot\\venv\\Lib\\site-packages\\aiogram\\bot\\api.py'>
  File "C:\xStorage\Projects\PrometeyBot\venv\Lib\site-packages\aiogram\bot\api.py", line 142, in make_request
    raise exceptions.NetworkError(f"aiohttp client throws an error: {e.__class__.__name__}: {e}")
          │          └ <class 'aiogram.utils.exceptions.NetworkError'>
          └ <module 'aiogram.utils.exceptions' from 'C:\\xStorage\\Projects\\PrometeyBot\\venv\\Lib\\site-packages\\aiogram\\utils\\excep...

aiogram.utils.exceptions.NetworkError: Aiohttp client throws an error: ClientConnectorError: Cannot connect to host api.telegram.org:443 ssl:default [getaddrinfo failed]
2023-07-01T18:41:29.327896+0300 ERROR An error has been caught in function 'drop_state', process 'MainProcess' (4296), thread 'MainThread' (5608):
Traceback (most recent call last):

  File "<frozen runpy>", line 198, in _run_module_as_main
  File "<frozen runpy>", line 88, in _run_code

  File "C:\xStorage\Projects\PrometeyBot\root\tg\main.py", line 772, in <module>
    executor.start_polling(dispatcher=dp, skip_updates=True, on_startup=on_startup)
    │        │                        │                                 └ <function on_startup at 0x00000262A0207600>
    │        │                        └ <aiogram.dispatcher.dispatcher.Dispatcher object at 0x000002629F869450>
    │        └ <function start_polling at 0x00000262FEE02020>
    └ <module 'aiogram.utils.executor' from 'C:\\xStorage\\Projects\\PrometeyBot\\venv\\Lib\\site-packages\\aiogram\\utils\\executo...

  File "C:\xStorage\Projects\PrometeyBot\venv\Lib\site-packages\aiogram\utils\executor.py", line 45, in start_polling
    executor.start_polling(
    │        └ <function Executor.start_polling at 0x00000262FEE02B60>
    └ <aiogram.utils.executor.Executor object at 0x00000262A011D710>
  File "C:\xStorage\Projects\PrometeyBot\venv\Lib\site-packages\aiogram\utils\executor.py", line 323, in start_polling
    loop.run_forever()
    │    └ <function ProactorEventLoop.run_forever at 0x00000262FCD71EE0>
    └ <ProactorEventLoop running=True closed=False debug=False>
  File "C:\Users\Dima Tatarin\AppData\Local\Programs\Python\Python311\Lib\asyncio\windows_events.py", line 321, in run_forever
    super().run_forever()
  File "C:\Users\Dima Tatarin\AppData\Local\Programs\Python\Python311\Lib\asyncio\base_events.py", line 607, in run_forever
    self._run_once()
    │    └ <function BaseEventLoop._run_once at 0x00000262FCCB3D80>
    └ <ProactorEventLoop running=True closed=False debug=False>
  File "C:\Users\Dima Tatarin\AppData\Local\Programs\Python\Python311\Lib\asyncio\base_events.py", line 1922, in _run_once
    handle._run()
    │      └ <function Handle._run at 0x00000262FCBDDC60>
    └ <Handle Task.task_wakeup(<Future finished result=None>)>
  File "C:\Users\Dima Tatarin\AppData\Local\Programs\Python\Python311\Lib\asyncio\events.py", line 80, in _run
    self._context.run(self._callback, *self._args)
    │    │            │    │           │    └ <member '_args' of 'Handle' objects>
    │    │            │    │           └ <Handle Task.task_wakeup(<Future finished result=None>)>
    │    │            │    └ <member '_callback' of 'Handle' objects>
    │    │            └ <Handle Task.task_wakeup(<Future finished result=None>)>
    │    └ <member '_context' of 'Handle' objects>
    └ <Handle Task.task_wakeup(<Future finished result=None>)>
  File "C:\xStorage\Projects\PrometeyBot\venv\Lib\site-packages\aiogram\dispatcher\handler.py", line 117, in notify
    response = await handler_obj.handler(*args, **partial_data)
                     │           │        │       └ {}
                     │           │        └ (<Update {"update_id": 56642233, "callback_query": {"id": "5831028021068234250", "from": {"id": 1357642007, "is_bot": false, ...
                     │           └ <bound method Dispatcher.process_update of <aiogram.dispatcher.dispatcher.Dispatcher object at 0x000002629F869450>>
                     └ Handler.HandlerObj(handler=<bound method Dispatcher.process_update of <aiogram.dispatcher.dispatcher.Dispatcher object at 0x0...
  File "C:\xStorage\Projects\PrometeyBot\venv\Lib\site-packages\aiogram\dispatcher\dispatcher.py", line 283, in process_update
    return await self.callback_query_handlers.notify(update.callback_query)
                 │    │                       │      │      └ <aiogram.types.fields.Field object at 0x00000262FEAED290>
                 │    │                       │      └ <Update {"update_id": 56642233, "callback_query": {"id": "5831028021068234250", "from": {"id": 1357642007, "is_bot": false, "...
                 │    │                       └ <function Handler.notify at 0x00000262FED1A2A0>
                 │    └ <aiogram.dispatcher.handler.Handler object at 0x00000262FE90F290>
                 └ <aiogram.dispatcher.dispatcher.Dispatcher object at 0x000002629F869450>
  File "C:\xStorage\Projects\PrometeyBot\venv\Lib\site-packages\aiogram\dispatcher\handler.py", line 117, in notify
    response = await handler_obj.handler(*args, **partial_data)
                     │           │        │       └ {'callback_data': {'@': 'Canc', 'receiver_id': '459471362', 'task_number': '2'}}
                     │           │        └ (<CallbackQuery {"id": "5831028021068234250", "from": {"id": 1357642007, "is_bot": false, "first_name": "KVASYAN", "username"...
                     │           └ <function drop_state at 0x00000262A0206C00>
                     └ Handler.HandlerObj(handler=<function drop_state at 0x00000262A0206C00>, spec=FullArgSpec(args=['callback_query', 'callback_da...

> File "C:\xStorage\Projects\PrometeyBot\root\tg\main.py", line 671, in drop_state
    reply_markup=get_ikb_to_check_users_tasks(receiver_id))
                 │                            └ '459471362'
                 └ <function get_ikb_to_check_users_tasks at 0x00000262FF473920>

TypeError: get_ikb_to_check_users_tasks() missing 1 required positional argument: 'task_number'
2023-07-01T18:41:29.471596+0300 ERROR Message is not modified: specified new message content and reply markup are exactly the same as a current content and reply markup of the message
Traceback (most recent call last):

  File "<frozen runpy>", line 198, in _run_module_as_main
  File "<frozen runpy>", line 88, in _run_code

  File "C:\xStorage\Projects\PrometeyBot\root\tg\main.py", line 772, in <module>
    executor.start_polling(dispatcher=dp, skip_updates=True, on_startup=on_startup)
    │        │                        │                                 └ <function on_startup at 0x00000262A0207600>
    │        │                        └ <aiogram.dispatcher.dispatcher.Dispatcher object at 0x000002629F869450>
    │        └ <function start_polling at 0x00000262FEE02020>
    └ <module 'aiogram.utils.executor' from 'C:\\xStorage\\Projects\\PrometeyBot\\venv\\Lib\\site-packages\\aiogram\\utils\\executo...

  File "C:\xStorage\Projects\PrometeyBot\venv\Lib\site-packages\aiogram\utils\executor.py", line 45, in start_polling
    executor.start_polling(
    │        └ <function Executor.start_polling at 0x00000262FEE02B60>
    └ <aiogram.utils.executor.Executor object at 0x00000262A011D710>
  File "C:\xStorage\Projects\PrometeyBot\venv\Lib\site-packages\aiogram\utils\executor.py", line 323, in start_polling
    loop.run_forever()
    │    └ <function ProactorEventLoop.run_forever at 0x00000262FCD71EE0>
    └ <ProactorEventLoop running=True closed=False debug=False>
  File "C:\Users\Dima Tatarin\AppData\Local\Programs\Python\Python311\Lib\asyncio\windows_events.py", line 321, in run_forever
    super().run_forever()
  File "C:\Users\Dima Tatarin\AppData\Local\Programs\Python\Python311\Lib\asyncio\base_events.py", line 607, in run_forever
    self._run_once()
    │    └ <function BaseEventLoop._run_once at 0x00000262FCCB3D80>
    └ <ProactorEventLoop running=True closed=False debug=False>
  File "C:\Users\Dima Tatarin\AppData\Local\Programs\Python\Python311\Lib\asyncio\base_events.py", line 1922, in _run_once
    handle._run()
    │      └ <function Handle._run at 0x00000262FCBDDC60>
    └ <Handle Task.task_wakeup(<Future finished result=None>)>
  File "C:\Users\Dima Tatarin\AppData\Local\Programs\Python\Python311\Lib\asyncio\events.py", line 80, in _run
    self._context.run(self._callback, *self._args)
    │    │            │    │           │    └ <member '_args' of 'Handle' objects>
    │    │            │    │           └ <Handle Task.task_wakeup(<Future finished result=None>)>
    │    │            │    └ <member '_callback' of 'Handle' objects>
    │    │            └ <Handle Task.task_wakeup(<Future finished result=None>)>
    │    └ <member '_context' of 'Handle' objects>
    └ <Handle Task.task_wakeup(<Future finished result=None>)>
  File "C:\xStorage\Projects\PrometeyBot\venv\Lib\site-packages\aiogram\dispatcher\handler.py", line 117, in notify
    response = await handler_obj.handler(*args, **partial_data)
                     │           │        │       └ {}
                     │           │        └ (<Update {"update_id": 56642233, "callback_query": {"id": "5831028021068234250", "from": {"id": 1357642007, "is_bot": false, ...
                     │           └ <bound method Dispatcher.process_update of <aiogram.dispatcher.dispatcher.Dispatcher object at 0x000002629F869450>>
                     └ Handler.HandlerObj(handler=<bound method Dispatcher.process_update of <aiogram.dispatcher.dispatcher.Dispatcher object at 0x0...
  File "C:\xStorage\Projects\PrometeyBot\venv\Lib\site-packages\aiogram\dispatcher\dispatcher.py", line 283, in process_update
    return await self.callback_query_handlers.notify(update.callback_query)
                 │    │                       │      │      └ <aiogram.types.fields.Field object at 0x00000262FEAED290>
                 │    │                       │      └ <Update {"update_id": 56642233, "callback_query": {"id": "5831028021068234250", "from": {"id": 1357642007, "is_bot": false, "...
                 │    │                       └ <function Handler.notify at 0x00000262FED1A2A0>
                 │    └ <aiogram.dispatcher.handler.Handler object at 0x00000262FE90F290>
                 └ <aiogram.dispatcher.dispatcher.Dispatcher object at 0x000002629F869450>
  File "C:\xStorage\Projects\PrometeyBot\venv\Lib\site-packages\aiogram\dispatcher\handler.py", line 117, in notify
    response = await handler_obj.handler(*args, **partial_data)
                     │           │        │       └ {'callback_data': {'@': 'Canc', 'receiver_id': '459471362', 'task_number': '2'}}
                     │           │        └ (<CallbackQuery {"id": "5831028021068234250", "from": {"id": 1357642007, "is_bot": false, "first_name": "KVASYAN", "username"...
                     │           └ <function drop_state at 0x00000262A0206C00>
                     └ Handler.HandlerObj(handler=<function drop_state at 0x00000262A0206C00>, spec=FullArgSpec(args=['callback_query', 'callback_da...

> File "C:\xStorage\Projects\PrometeyBot\root\tg\main.py", line 670, in drop_state
    await bot.edit_message_reply_markup(not_checked_task_obj.admin_id, not_checked_task_obj.message_id,
          │   │                         │                    │         │                    └ <sqlalchemy.orm.attributes.InstrumentedAttribute object at 0x00000262FF1F6160>
          │   │                         │                    │         └ <root.db.models.NotCheckedTask object at 0x00000262A168E210>
          │   │                         │                    └ <sqlalchemy.orm.attributes.InstrumentedAttribute object at 0x00000262FF1F6020>
          │   │                         └ <root.db.models.NotCheckedTask object at 0x00000262A168E210>
          │   └ <function Bot.edit_message_reply_markup at 0x00000262FEB267A0>
          └ <aiogram.bot.bot.Bot object at 0x00000262FAB94F10>

  File "C:\xStorage\Projects\PrometeyBot\venv\Lib\site-packages\aiogram\bot\bot.py", line 3252, in edit_message_reply_markup
    result = await self.request(api.Methods.EDIT_MESSAGE_REPLY_MARKUP, payload)
                   │    │       │   │       │                          └ {'chat_id': '1357642007', 'message_id': '1855'}
                   │    │       │   │       └ <aiogram.utils.helper.Item object at 0x00000262FEAF85D0>
                   │    │       │   └ <class 'aiogram.bot.api.Methods'>
                   │    │       └ <module 'aiogram.bot.api' from 'C:\\xStorage\\Projects\\PrometeyBot\\venv\\Lib\\site-packages\\aiogram\\bot\\api.py'>
                   │    └ <function BaseBot.request at 0x00000262FEAF5B20>
                   └ <aiogram.bot.bot.Bot object at 0x00000262FAB94F10>
  File "C:\xStorage\Projects\PrometeyBot\venv\Lib\site-packages\aiogram\bot\base.py", line 236, in request
    return await api.make_request(await self.get_session(), self.server, self.__token, method, data, files,
                 │   │                  │    │              │    │       │             │       │     └ None
                 │   │                  │    │              │    │       │             │       └ {'chat_id': '1357642007', 'message_id': '1855'}
                 │   │                  │    │              │    │       │             └ 'editMessageReplyMarkup'
                 │   │                  │    │              │    │       └ <aiogram.bot.bot.Bot object at 0x00000262FAB94F10>
                 │   │                  │    │              │    └ TelegramAPIServer(base='https://api.telegram.org/bot{token}/{method}', file='https://api.telegram.org/file/bot{token}/{path}')
                 │   │                  │    │              └ <aiogram.bot.bot.Bot object at 0x00000262FAB94F10>
                 │   │                  │    └ <function BaseBot.get_session at 0x00000262FEAF5300>
                 │   │                  └ <aiogram.bot.bot.Bot object at 0x00000262FAB94F10>
                 │   └ <function make_request at 0x00000262FEAF4220>
                 └ <module 'aiogram.bot.api' from 'C:\\xStorage\\Projects\\PrometeyBot\\venv\\Lib\\site-packages\\aiogram\\bot\\api.py'>
  File "C:\xStorage\Projects\PrometeyBot\venv\Lib\site-packages\aiogram\bot\api.py", line 140, in make_request
    return check_result(method, response.content_type, response.status, await response.text())
           │            │       │        │             │        │             │        └ <function ClientResponse.text at 0x00000262FE61BCE0>
           │            │       │        │             │        │             └ <ClientResponse(https://api.telegram.org/bot5724555976:AAFxd0Ipy9YSR4ZgYBDa-iypq-m1QK2-vp4/editMessageReplyMarkup) [400 Bad R...
           │            │       │        │             │        └ 400
           │            │       │        │             └ <ClientResponse(https://api.telegram.org/bot5724555976:AAFxd0Ipy9YSR4ZgYBDa-iypq-m1QK2-vp4/editMessageReplyMarkup) [400 Bad R...
           │            │       │        └ <property object at 0x00000262FE4BE5C0>
           │            │       └ <ClientResponse(https://api.telegram.org/bot5724555976:AAFxd0Ipy9YSR4ZgYBDa-iypq-m1QK2-vp4/editMessageReplyMarkup) [400 Bad R...
           │            └ 'editMessageReplyMarkup'
           └ <function check_result at 0x00000262FEAF4360>
  File "C:\xStorage\Projects\PrometeyBot\venv\Lib\site-packages\aiogram\bot\api.py", line 115, in check_result
    exceptions.BadRequest.detect(description)
    │          │          │      └ 'Bad Request: message is not modified: specified new message content and reply markup are exactly the same as a current conte...
    │          │          └ <classmethod(<function _MatchErrorMixin.detect at 0x00000262FE902520>)>
    │          └ <class 'aiogram.utils.exceptions.BadRequest'>
    └ <module 'aiogram.utils.exceptions' from 'C:\\xStorage\\Projects\\PrometeyBot\\venv\\Lib\\site-packages\\aiogram\\utils\\excep...
  File "C:\xStorage\Projects\PrometeyBot\venv\Lib\site-packages\aiogram\utils\exceptions.py", line 140, in detect
    raise err(cls.text or description)
          │   │   │       └ 'bad request: message is not modified: specified new message content and reply markup are exactly the same as a current conte...
          │   │   └ None
          │   └ <class 'aiogram.utils.exceptions.BadRequest'>
          └ <class 'aiogram.utils.exceptions.MessageNotModified'>

aiogram.utils.exceptions.MessageNotModified: Message is not modified: specified new message content and reply markup are exactly the same as a current content and reply markup of the message
